# üõë Exce√ß√µes e Manipula√ß√£o de Exece√ß√µes

Os recursos de manipula√ß√£o da linguagem C# ajudam a lidar com quaisquer situa√ß√µes excepcionais ou inesperadas que ocorram
durante a execu√ß√£o de um programa.

## Exce√ß√µes
Exce√ß√µes s√£o representadas por classes derivadas de [Exception](https://docs.microsoft.com/en-us/dotnet/api/system.exception?view=netcore-3.1), elas s√£o mecanismos prim√°rios do C# para comunicar um estado de erro em seu software. 

No exemplo a seguir temos o m√©todo `BuyProduct` que verifica se um prroduto est√° dispon√≠vel para compra. Caso o mesmo n√£o esteja,
√© lan√ßada a exce√ß√£o `ProductNotAvailableException` utilizando a instru√ß√£o `throw`, que ir√° gerar um erro em seu programa.
```C#
class ProductNotAvailableException : Exeception
{
    public ProductNotAvailableException(string message) : base(message)
    {
    }
}

class ProductStore
{
    List<string> products = new List<string>() { "ps4", "xbox", "iphone 10" };
    
    public void BuyProduct(string product)
    {
        if (!products.Contains(product))
        {
            throw  new ProductNotAvailableException($"Erro: Situa√ß√£o n√£o esperada, o produto n√£o existe!");
        }
    }
}
```

## Manipula√ß√£o de Exce√ß√µes
No C#, os erros no programa em tempo de execu√ß√£o s√£o **propagados** pelo programa usando um mecanismo chamado **exce√ß√µes**. Uma vez que a exce√ß√£o √© gerada,
ela ir√° mostrar uma caixa de di√°logo exibindo o erro em seu programa. Por√©m podemos capturar esta exce√ß√£o utilizando a instru√ß√£o `try` e `catch`.

```
try
{
    // C√≥digo que ir√° lan√ßar uma exce√ß√£o em uma situa√ß√£o inesperada.
}
catch (Exception ex)
{
    // Caso o bloco 'try' lance uma exce√ß√£o, a mesma ser√° capturada
    // pelo 'catch' e este trecho de c√≥digo ser√° executado:
    Console.WriteLine("Exce√ß√£o capturada!);
}
```


```C#

class ProductStore
{
    List<string> products = new List<string>() { "ps4", "xbox", "iphone 10" };
    
    public void BuyProduct(string product)
    {
        try
        {
            if (!products.Contains(product))
            {
                throw new ProductNotAvailableException($"Erro: Situa√ß√£o n√£o esperada, o produto n√£o existe!");
            }
        }
        catch(ProductNotAvailableException exception)
        {
            Console.WriteLine("O produto n√£o pode ser comprado pois n√£o est√° dispon√≠vel");
        }
    }
}
```
Uma instru√ß√£o `try` pode conter mais de um bloco `catch`. A primeira instru√ß√£o `catch` que puder capcturar a `Exception` √© executado.
Qualquer `catch` posterior, √© ignorado. Portanto os blocos de captura `catch` devem ser ordenados dos mais espec√≠ficos para os menos espec√≠ficos.

Antes do bloco `catch` ser executado, √© verificado se existe um bloco `finally`. O bloco `finally` permite que o programador
trate estados amb√≠guos que podem ter acontecido durante o lan√ßamento da exce√ß√£o.
```C#
public class ExceptionExample
{
    static void Main()
    {
        StreamWriter sw;
        
        try
        {
            using(sw = new StreamWriter(@"C:\test\test.txt"))
            {
                sw.WriteLine("Hello");
            }
        }
        
        // Exce√ß√£o mais espec√≠fica primeiro
        catch (DirectoryNotFoundException ex)
        {
            Console.WriteLine(ex);
        }
        catch (FileNotFoundException ex)
        {
            Console.WriteLine(ex);
        }
        // Exce√ß√£o menos espec√≠fica por √∫ltimo
        catch (IOException ex)
        {
            Console.WriteLine(ex);
        }
        finally
        {
            Console.WriteLine("Executado com sucesso");
            
            // Caso algum erro tenha acontecido, verifica se sw foi fechado.
            // Se n√£o foi, fecha.
            if (sw != null)
            {
                sw.Close();
            }
        }
    }
}
```

# Refer√™ncias

* [Exceptions and Exception Handling](https://docs.microsoft.com/en-us/dotnet/csharp/programming-guide/exceptions/)